Workbook

Sheet Campanhas
A1: Campanha | B1: Desembolso | C1: Vencimento/Pagto
A2: Acelera Sul - PR/MS Black | B2: 46357 | C2: 46512
A3: Acelera Sul - PR/MS Black + | B3: 46357 | C3: 46512
A4: Acelera Sul - PR/MS Silver + | B4: 46357 | C4: 46512
A5: Acelera Sul - PR/MS Silver | B5: 46357 | C5: 46512
A6: Acelera Sul - RS/SC Black Venc. Maio | B6: 46327 | C6: 46512
A7: Acelera Sul - RS/SC Black + Venc. Maio | B7: 46327 | C7: 46512
A8: Acelera Sul - RS/SC Silver + Venc. Maio | B8: 46327 | C8: 46512
A9: Acelera Sul - RS/SC Silver Venc. Maio | B9: 46327 | C9: 46512
A10: Acelera Sul - RS/SC Black Venc. Junho | B10: 46327 | C10: 46543
A11: Acelera Sul - RS/SC Black + Venc. Junho | B11: 46327 | C11: 46543
A12: Acelera Sul - RS/SC Silver + Venc. Junho | B12: 46327 | C12: 46543
A13: Acelera Sul - RS/SC Silver Venc. Junho | B13: 46327 | C13: 46543
... A23: Verão | B23: 46296 | C23: 46512

Sheet Taxas
A1: Campanha | B1: Produto Financeiro | C1: Produto Agrícola | D1: Moeda | E1: Cálculo Período | F1: Tipo Juros | G1: Taxa (a.m.) | H1: Desconto Comercial (VPAN) | I1: Incentivo | J1: Início Vigência | K1: Fim Vigência | L1: Vencimento/Pagto CAMPANHA | M1: Desembolso CAMPANHA | N1: Desembolso Especifico Taxa
A2: Acelera Sul - PR/MS Black + | B2: Syde | C2: Crop | D2: Real | E2: Uteis | F2: Composto | G2: 0.0175 | H2: 0.04 | J2: 46113 | K2: 46127 | L2: =IFERROR(VLOOKUP(Tabela2[[#This Row],[Campanha]],Campanhas!A:C,3,FALSE),"") -> 46512 | M2: =IFERROR(VLOOKUP(Tabela2[[#This Row],[Campanha]],Campanhas!A:C,2,FALSE),"") -> 46357
A3: Acelera Sul - PR/MS Black + | B3: Fiso | C3: Crop | D3: Real | E3: Corridos | F3: Simples | G3: 0.0185 | I3: 0.04 | J3: 46113 | K3: 46127 | L3: =IFERROR(VLOOKUP(Tabela2[[#This Row],[Campanha]],Campanhas!A:C,3,FALSE),"") -> 46512 | M3: =IFERROR(VLOOKUP(Tabela2[[#This Row],[Campanha]],Campanhas!A:C,2,FALSE),"") -> 46357
A4: Acelera Sul - PR/MS Black + | B4: Syngenta | C4: Crop | D4: Real | E4: Corridos | F4: Simples | G4: 0.0185 | J4: 46113 | K4: 46127 | L4: =IFERROR(VLOOKUP(Tabela2[[#This Row],[Campanha]],Campanhas!A:C,3,FALSE),"") -> 46512 | M4: =IFERROR(VLOOKUP(Tabela2[[#This Row],[Campanha]],Campanhas!A:C,2,FALSE),"") -> 46357
A5: Acelera Sul - PR/MS Black | B5: Syde | C5: Crop | D5: Real | E5: Uteis | F5: Composto | G5: 0.0185 | H5: 0.04 | J5: 46113 | K5: 46127 | L5: =IFERROR(VLOOKUP(Tabela2[[#This Row],[Campanha]],Campanhas!A:C,3,FALSE),"") -> 46512 | M5: =IFERROR(VLOOKUP(Tabela2[[#This Row],[Campanha]],Campanhas!A:C,2,FALSE),"") -> 46357
A6: Acelera Sul - PR/MS Black | B6: Fiso | C6: Crop | D6: Real | E6: Corridos | F6: Simples | G6: 0.0185 | I6: 0.03 | J6: 46113 | K6: 46127 | L6: =IFERROR(VLOOKUP(Tabela2[[#This Row],[Campanha]],Campanhas!A:C,3,FALSE),"") -> 46512 | M6: =IFERROR(VLOOKUP(Tabela2[[#This Row],[Campanha]],Campanhas!A:C,2,FALSE),"") -> 46357
A7: Acelera Sul - PR/MS Black | B7: Syngenta | C7: Crop | D7: Real | E7: Corridos | F7: Simples | G7: 0.0185 | J7: 46113 | K7: 46127 | L7: =IFERROR(VLOOKUP(Tabela2[[#This Row],[Campanha]],Campanhas!A:C,3,FALSE),"") -> 46512 | M7: =IFERROR(VLOOKUP(Tabela2[[#This Row],[Campanha]],Campanhas!A:C,2,FALSE),"") -> 46357
A8: Acelera Sul - PR/MS Silver + | B8: Fiso | C8: Crop | D8: Real | E8: Corridos | F8: Simples | G8: 0.0185 | I8: 0.01 | J8: 46113 | K8: 46127 | L8: =IFERROR(VLOOKUP(Tabela2[[#This Row],[Campanha]],Campanhas!A:C,3,FALSE),"") -> 46512 | M8: =IFERROR(VLOOKUP(Tabela2[[#This Row],[Campanha]],Campanhas!A:C,2,FALSE),"") -> 46357
A9: Acelera Sul - PR/MS Silver + | B9: Syngenta | C9: Crop | D9: Real | E9: Corridos | F9: Simples | G9: 0.0185 | J9: 46113 | K9: 46127 | L9: =IFERROR(VLOOKUP(Tabela2[[#This Row],[Campanha]],Campanhas!A:C,3,FALSE),"") -> 46512 | M9: =IFERROR(VLOOKUP(Tabela2[[#This Row],[Campanha]],Campanhas!A:C,2,FALSE),"") -> 46357
A10: Acelera Sul - PR/MS Silver | B10: Fiso | C10: Crop | D10: Real | E10: Corridos | F10: Simples | G10: 0.0185 | I10: 0.01 | J10: 46113 | K10: 46127 | L10: =IFERROR(VLOOKUP(Tabela2[[#This Row],[Campanha]],Campanhas!A:C,3,FALSE),"") -> 46512 | M10: =IFERROR(VLOOKUP(Tabela2[[#This Row],[Campanha]],Campanhas!A:C,2,FALSE),"") -> 46357
A11: Acelera Sul - PR/MS Silver | B11: Syngenta | C11: Crop | D11: Real | E11: Corridos | F11: Simples | G11: 0.0185 | J11: 46113 | K11: 46127 | L11: =IFERROR(VLOOKUP(Tabela2[[#This Row],[Campanha]],Campanhas!A:C,3,FALSE),"") -> 46512 | M11: =IFERROR(VLOOKUP(Tabela2[[#This Row],[Campanha]],Campanhas!A:C,2,FALSE),"") -> 46357
A12: Acelera Sul - PR/MS | B12: Syngenta | C12: Bio | D12: Real | E12: Corridos | F12: Simples | G12: 0.0185 | J12: 46113 | K12: 46127 | L12: =IFERROR(VLOOKUP(Tabela2[[#This Row],[Campanha]],Campanhas!A:C,3,FALSE),"") -> 46512 | M12: =IFERROR(VLOOKUP(Tabela2[[#This Row],[Campanha]],Campanhas!A:C,2,FALSE),"") -> 46357
A13: Acelera Sul - PR/MS | B13: Syde | C13: Bio | D13: Real | E13: Uteis | F13: Composto | G13: 0.017 | H13: 0.04 | J13: 46113 | K13: 46127 | L13: =IFERROR(VLOOKUP(Tabela2[[#This Row],[Campanha]],Campanhas!A:C,3,FALSE),"") -> 46512 | M13: =IFERROR(VLOOKUP(Tabela2[[#This Row],[Campanha]],Campanhas!A:C,2,FALSE),"") -> 46357
A14: Acelera Sul - RS/SC Venc. Maio | B14: Syde | C14: Bio | D14: Real | E14: Uteis | F14: Composto | G14: 0.0166 | H14: 0.04 | J14: 46113 | K14: 46127 | L14: =IFERROR(VLOOKUP(Tabela2[[#This Row],[Campanha]],Campanhas!A:C,3,FALSE),"") -> 46512 | M14: =IFERROR(VLOOKUP(Tabela2[[#This Row],[Campanha]],Campanhas!A:C,2,FALSE),"") -> 46327
A15: Acelera Sul - RS/SC Venc. Maio | B15: Syngenta | C15: Bio | D15: Real | E15: Corridos | F15: Simples | G15: 0.0185 | J15: 46113 | K15: 46127 | L15: =IFERROR(VLOOKUP(Tabela2[[#This Row],[Campanha]],Campanhas!A:C,3,FALSE),"") -> 46512 | M15: =IFERROR(VLOOKUP(Tabela2[[#This Row],[Campanha]],Campanhas!A:C,2,FALSE),"") -> 46327
A16: Acelera Sul - RS/SC Venc. Junho | B16: Syde | C16: Bio | D16: Real | E16: Uteis | F16: Composto | G16: 0.0165 | H16: 0.04 | J16: 46113 | K16: 46127 | L16: =IFERROR(VLOOKUP(Tabela2[[#This Row],[Campanha]],Campanhas!A:C,3,FALSE),"") -> 46543 | M16: =IFERROR(VLOOKUP(Tabela2[[#This Row],[Campanha]],Campanhas!A:C,2,FALSE),"") -> 46327
A17: Acelera Sul - RS/SC Venc. Junho | B17: Syngenta | C17: Bio | D17: Real | E17: Corridos | F17: Simples | G17: 0.0185 | J17: 46113 | K17: 46127 | L17: =IFERROR(VLOOKUP(Tabela2[[#This Row],[Campanha]],Campanhas!A:C,3,FALSE),"") -> 46543 | M17: =IFERROR(VLOOKUP(Tabela2[[#This Row],[Campanha]],Campanhas!A:C,2,FALSE),"") -> 46327
A18: OTO Royal - Soja | B18: Syde | C18: Crop | D18: Dolar | E18: Corridos | F18: Simples | G18: 0.01 | H18: 0.04 | J18: 46113 | K18: 46127 | L18: =IFERROR(VLOOKUP(Tabela2[[#This Row],[Campanha]],Campanhas!A:C,3,FALSE),"") -> 46512 | M18: =IFERROR(VLOOKUP(Tabela2[[#This Row],[Campanha]],Campanhas!A:C,2,FALSE),"") -> 46300
A19: OTO Royal - Soja | B19: Fiso | C19: Crop | D19: Dolar | E19: Corridos | F19: Simples | G19: 0.012 | I19: 0.04 | J19: 46113 | K19: 46127 | L19: =IFERROR(VLOOKUP(Tabela2[[#This Row],[Campanha]],Campanhas!A:C,3,FALSE),"") -> 46512 | M19: =IFERROR(VLOOKUP(Tabela2[[#This Row],[Campanha]],Campanhas!A:C,2,FALSE),"") -> 46300
A20: OTO Royal - Soja | B20: Syngenta | C20: Crop | D20: Dolar | E20: Corridos | F20: Simples | G20: 0.012 | J20: 46113 | K20: 46127 | L20: =IFERROR(VLOOKUP(Tabela2[[#This Row],[Campanha]],Campanhas!A:C,3,FALSE),"") -> 46512 | M20: =IFERROR(VLOOKUP(Tabela2[[#This Row],[Campanha]],Campanhas!A:C,2,FALSE),"") -> 46300
A21: OTO Black - Soja | B21: Syde | C21: Crop | D21: Dolar | E21: Corridos | F21: Simples | G21: 0.011 | H21: 0.04 | J21: 46113 | K21: 46127 | L21: =IFERROR(VLOOKUP(Tabela2[[#This Row],[Campanha]],Campanhas!A:C,3,FALSE),"") -> 46512 | M21: =IFERROR(VLOOKUP(Tabela2[[#This Row],[Campanha]],Campanhas!A:C,2,FALSE),"") -> 46300
A22: OTO Black - Soja | B22: Fiso | C22: Crop | D22: Dolar | E22: Corridos | F22: Simples | G22: 0.012 | I22: 0.02 | J22: 46113 | K22: 46127 | L22: =IFERROR(VLOOKUP(Tabela2[[#This Row],[Campanha]],Campanhas!A:C,3,FALSE),"") -> 46512 | M22: =IFERROR(VLOOKUP(Tabela2[[#This Row],[Campanha]],Campanhas!A:C,2,FALSE),"") -> 46300
A23: OTO Black - Soja | B23: Syngenta | C23: Crop | D23: Dolar | E23: Corridos | F23: Simples | G23: 0.012 | J23: 46113 | K23: 46127 | L23: =IFERROR(VLOOKUP(Tabela2[[#This Row],[Campanha]],Campanhas!A:C,3,FALSE),"") -> 46512 | M23: =IFERROR(VLOOKUP(Tabela2[[#This Row],[Campanha]],Campanhas!A:C,2,FALSE),"") -> 46300
A24: OTO Silver - Soja | B24: Fiso | C24: Crop | D24: Dolar | E24: Corridos | F24: Simples | G24: 0.012 | I24: 0.01 | J24: 46113 | K24: 46127 | L24: =IFERROR(VLOOKUP(Tabela2[[#This Row],[Campanha]],Campanhas!A:C,3,FALSE),"") -> 46512 | M24: =IFERROR(VLOOKUP(Tabela2[[#This Row],[Campanha]],Campanhas!A:C,2,FALSE),"") -> 46300
A25: OTO Silver - Soja | B25: Syngenta | C25: Crop | D25: Dolar | E25: Corridos | F25: Simples | G25: 0.012 | J25: 46113 | K25: 46127 | L25: =IFERROR(VLOOKUP(Tabela2[[#This Row],[Campanha]],Campanhas!A:C,3,FALSE),"") -> 46512 | M25: =IFERROR(VLOOKUP(Tabela2[[#This Row],[Campanha]],Campanhas!A:C,2,FALSE),"") -> 46300
A26: OTO Royal - Milho | B26: Syde | C26: Crop | D26: Dolar | E26: Corridos | F26: Simples | G26: 0.0096 | H26: 0.04 | J26: 46113 | K26: 46127 | L26: =IFERROR(VLOOKUP(Tabela2[[#This Row],[Campanha]],Campanhas!A:C,3,FALSE),"") -> 46635 | M26: =IFERROR(VLOOKUP(Tabela2[[#This Row],[Campanha]],Campanhas!A:C,2,FALSE),"") -> 46371
A27: OTO Royal - Milho | B27: Syngenta | C27: Crop | D27: Dolar | E27: Corridos | F27: Simples | G27: 0.012 | L27: =IFERROR(VLOOKUP(Tabela2[[#This Row],[Campanha]],Campanhas!A:C,3,FALSE),"") -> 46635 | M27: 46451
A28: OTO Black - Milho | B28: Syde | C28: Crop | D28: Dolar | E28: Corridos | F28: Simples | G28: 0.0106 | H28: 0.04 | J28: 46113 | K28: 46127 | L28: =IFERROR(VLOOKUP(Tabela2[[#This Row],[Campanha]],Campanhas!A:C,3,FALSE),"") -> 46635 | M28: =IFERROR(VLOOKUP(Tabela2[[#This Row],[Campanha]],Campanhas!A:C,2,FALSE),"") -> 46371
A29: OTO Black - Milho | B29: Syngenta | C29: Crop | D29: Dolar | E29: Corridos | F29: Simples | G29: 0.012 | J29: 46113 | K29: 46127 | L29: =IFERROR(VLOOKUP(Tabela2[[#This Row],[Campanha]],Campanhas!A:C,3,FALSE),"") -> 46635 | M29: 46451
A30: Verão | B30: Syde | C30: Crop/ Seed Care | D30: Real | E30: Uteis | F30: Composto | G30: 0.0176 | H30: 0.04 | J30: 46113 | K30: 46127 | L30: =IFERROR(VLOOKUP(Tabela2[[#This Row],[Campanha]],Campanhas!A:C,3,FALSE),"") -> 46512 | M30: =IFERROR(VLOOKUP(Tabela2[[#This Row],[Campanha]],Campanhas!A:C,2,FALSE),"") -> 46296
A31: Verão | B31: Fiso | C31: Crop/ Seed Care | D31: Real | E31: Corridos | F31: Simples | G31: 0.0185 | I31: 0.01 | J31: 46113 | K31: 46127 | L31: =IFERROR(VLOOKUP(Tabela2[[#This Row],[Campanha]],Campanhas!A:C,3,FALSE),"") -> 46512 | M31: =IFERROR(VLOOKUP(Tabela2[[#This Row],[Campanha]],Campanhas!A:C,2,FALSE),"") -> 46296
A32: Verão | B32: Syngenta | C32: Crop/ Seed Care | D32: Real | E32: Corridos | F32: Simples | G32: 0.0185 | J32: 46113 | K32: 46127 | L32: =IFERROR(VLOOKUP(Tabela2[[#This Row],[Campanha]],Campanhas!A:C,3,FALSE),"") -> 46512 | M32: =IFERROR(VLOOKUP(Tabela2[[#This Row],[Campanha]],Campanhas!A:C,2,FALSE),"") -> 46296
A33: Verão | B33: Syde | C33: Bio | D33: Real | E33: Uteis | F33: Composto | G33: 0.0164 | H33: 0.04 | J33: 46113 | K33: 46127 | L33: =IFERROR(VLOOKUP(Tabela2[[#This Row],[Campanha]],Campanhas!A:C,3,FALSE),"") -> 46512 | M33: =IFERROR(VLOOKUP(Tabela2[[#This Row],[Campanha]],Campanhas!A:C,2,FALSE),"") -> 46296
A34: Verão | B34: Syngenta | C34: Bio | D34: Real | E34: Corridos | F34: Simples | G34: 0.0185 | J34: 46113 | K34: 46127 | L34: =IFERROR(VLOOKUP(Tabela2[[#This Row],[Campanha]],Campanhas!A:C,3,FALSE),"") -> 46512 | M34: =IFERROR(VLOOKUP(Tabela2[[#This Row],[Campanha]],Campanhas!A:C,2,FALSE),"") -> 46296
A35: Verão | B35: Syde | C35: Selo ESG Seed Care | D35: Dolar | E35: Corridos | F35: Simples | G35: 0.0114 | H35: 0.04 | L35: =IFERROR(VLOOKUP(Tabela2[[#This Row],[Campanha]],Campanhas!A:C,3,FALSE),"") -> 46512 | M35: =IFERROR(VLOOKUP(Tabela2[[#This Row],[Campanha]],Campanhas!A:C,2,FALSE),"") -> 46296
A36: Verão | B36: Fiso | C36: Selo ESG Seed Care | D36: Dolar | E36: Corridos | F36: Simples | G36: 0.012 | I36: 0.01 | L36: =IFERROR(VLOOKUP(Tabela2[[#This Row],[Campanha]],Campanhas!A:C,3,FALSE),"") -> 46512 | M36: =IFERROR(VLOOKUP(Tabela2[[#This Row],[Campanha]],Campanhas!A:C,2,FALSE),"") -> 46296
A37: Verão | B37: Syngenta | C37: Selo ESG Seed Care | D37: Dolar | E37: Corridos | F37: Simples | G37: 0.012 | L37: =IFERROR(VLOOKUP(Tabela2[[#This Row],[Campanha]],Campanhas!A:C,3,FALSE),"") -> 46512 | M37: =IFERROR(VLOOKUP(Tabela2[[#This Row],[Campanha]],Campanhas!A:C,2,FALSE),"") -> 46296
A38: Verão | B38: Syde | C38: Selo ESG Seed Care | D38: Real | E38: Uteis | F38: Composto | G38: 0.0164 | H38: 0.04 | J38: 46113 | K38: 46127 | L38: =IFERROR(VLOOKUP(Tabela2[[#This Row],[Campanha]],Campanhas!A:C,3,FALSE),"") -> 46512 | M38: =IFERROR(VLOOKUP(Tabela2[[#This Row],[Campanha]],Campanhas!A:C,2,FALSE),"") -> 46296
A39: Verão | B39: Fiso | C39: Selo ESG Seed Care | D39: Real | E39: Corridos | F39: Simples | G39: 0.0185 | I39: 0.03 | J39: 46113 | K39: 46127 | L39: =IFERROR(VLOOKUP(Tabela2[[#This Row],[Campanha]],Campanhas!A:C,3,FALSE),"") -> 46512 | M39: =IFERROR(VLOOKUP(Tabela2[[#This Row],[Campanha]],Campanhas!A:C,2,FALSE),"") -> 46296
A40: Verão | B40: Syngenta | C40: Selo ESG Seed Care | D40: Real | E40: Corridos | F40: Simples | G40: 0.0185 | J40: 46113 | K40: 46127 | L40: =IFERROR(VLOOKUP(Tabela2[[#This Row],[Campanha]],Campanhas!A:C,3,FALSE),"") -> 46512 | M40: =IFERROR(VLOOKUP(Tabela2[[#This Row],[Campanha]],Campanhas!A:C,2,FALSE),"") -> 46296
...

Sheet Simulador
B2: CAMPANHA | D2: Produto Agricola | F2: MOEDA
B3: Acelera Sul - PR/MS Black | D3: Crop | F3: Real
B7: DESEMBOLSO | D7: VENCIMENTO | F7: Valor Solicitado
B8: {=_xlfn.LET( _xlpm.camp,$B$3, _xlpm.prod,$D$3, _xlpm.moeda,$F$3, _xlpm.filtro,(Tabela2[Campanha]=_xlpm.camp)* (Tabela2[Moeda]=_xlpm.moeda)* (Tabela2[Produto Agrícola]=IF(_xlpm.prod="","",_xlpm.prod)), IFERROR( INDEX(_xlfn._xlws.FILTER(Tabela2[Desembolso CAMPANHA],_xlpm.filtro,""),1), "" ) )} -> 46357 | D8: {=_xlfn.LET( _xlpm.camp,$B$3, _xlpm.prod,$D$3, _xlpm.moeda,$F$3, _xlpm.filtro,(Tabela2[Campanha]=_xlpm.camp)* (Tabela2[Moeda]=_xlpm.moeda)* (Tabela2[Produto Agrícola]=IF(_xlpm.prod="","",_xlpm.prod)), IFERROR( INDEX(_xlfn._xlws.FILTER(Tabela2[Vencimento/Pagto CAMPANHA],_xlpm.filtro,""),1), "" ) )} -> 46512 | F8: 100
A13: VALIDAÇÃO: QTD DE LINHAS RETORNADAS | B13: =_xlfn.LET( _xlpm.camp,$B$3, _xlpm.prod,$D$3, _xlpm.moeda,$F$3, COUNTIFS( Tabela2[Campanha],_xlpm.camp, Tabela2[Moeda],_xlpm.moeda, Tabela2[Produto Financeiro],"Syde", Tabela2[Produto Agrícola],IF(_xlpm.prod="","",_xlpm.prod) ) ) -> 2 | D13: =_xlfn.LET( _xlpm.camp,$B$3, _xlpm.prod,$D$3, _xlpm.moeda,$F$3, COUNTIFS( Tabela2[Campanha],_xlpm.camp, Tabela2[Moeda],_xlpm.moeda, Tabela2[Produto Financeiro],"Fiso", Tabela2[Produto Agrícola],IF(_xlpm.prod="","",_xlpm.prod) ) ) -> 2 | F13: =_xlfn.LET( _xlpm.camp,$B$3, _xlpm.prod,$D$3, _xlpm.moeda,$F$3, COUNTIFS( Tabela2[Campanha],_xlpm.camp, Tabela2[Moeda],_xlpm.moeda, Tabela2[Produto Financeiro],"Syngenta", Tabela2[Produto Agrícola],IF(_xlpm.prod="","",_xlpm.prod) ) ) -> 2
B14: SYDE | D14: FISO | F14: SYNGENTA
A16: Valor Solicitado | B16: =F8 -> 100 | D16: =F8 -> 100 | F16: =F8 -> 100
A17: Desconto Comercial | B17: {=_xlfn.LET( _xlpm.camp,$B$3, _xlpm.prod,$D$3, _xlpm.moeda,$F$3, _xlpm.filtro,(Tabela2[Campanha]=_xlpm.camp)* (Tabela2[Moeda]=_xlpm.moeda)* (Tabela2[Produto Agrícola]=IF(_xlpm.prod="","",_xlpm.prod))* (Tabela2[Produto Financeiro]="Syde"), IFERROR( INDEX(_xlfn._xlws.FILTER(Tabela2[Desconto Comercial (VPAN)],_xlpm.filtro,""),1), 0 ) )} -> 0.04 | D17: {=_xlfn.LET( _xlpm.camp,$B$3, _xlpm.prod,$D$3, _xlpm.moeda,$F$3, _xlpm.filtro,(Tabela2[Campanha]=_xlpm.camp)* (Tabela2[Moeda]=_xlpm.moeda)* (Tabela2[Produto Agrícola]=IF(_xlpm.prod="","",_xlpm.prod))* (Tabela2[Produto Financeiro]="Fiso"), IFERROR( INDEX(_xlfn._xlws.FILTER(Tabela2[Desconto Comercial (VPAN)],_xlpm.filtro,""),1), 0 ) )} -> 0 | F17: {=_xlfn.LET( _xlpm.camp,$B$3, _xlpm.prod,$D$3, _xlpm.moeda,$F$3, _xlpm.filtro,(Tabela2[Campanha]=_xlpm.camp)* (Tabela2[Moeda]=_xlpm.moeda)* (Tabela2[Produto Agrícola]=IF(_xlpm.prod="","",_xlpm.prod))* (Tabela2[Produto Financeiro]="Syngenta"), IFERROR( INDEX(_xlfn._xlws.FILTER(Tabela2[Desconto Comercial (VPAN)],_xlpm.filtro,""),1), 0 ) )} -> 0
A18: Taxa de Juros (a.m.)* | B18: {=_xlfn.LET( _xlpm.camp,$B$3, _xlpm.prod,$D$3, _xlpm.moeda,$F$3, _xlpm.filtro,(Tabela2[Campanha]=_xlpm.camp)* (Tabela2[Moeda]=_xlpm.moeda)* (Tabela2[Produto Agrícola]=IF(_xlpm.prod="","",_xlpm.prod))* (Tabela2[Produto Financeiro]="Syde"), IFERROR(INDEX(_xlfn._xlws.FILTER(Tabela2[Taxa (a.m.)],_xlpm.filtro,""),1),0) )} -> 0.0185 | D18: {=_xlfn.LET( _xlpm.camp,$B$3, _xlpm.prod,$D$3, _xlpm.moeda,$F$3, _xlpm.filtro,(Tabela2[Campanha]=_xlpm.camp)* (Tabela2[Moeda]=_xlpm.moeda)* (Tabela2[Produto Agrícola]=IF(_xlpm.prod="","",_xlpm.prod))* (Tabela2[Produto Financeiro]="Fiso"), IFERROR(INDEX(_xlfn._xlws.FILTER(Tabela2[Taxa (a.m.)],_xlpm.filtro,""),1),0) )} -> 0.0185 | F18: {=_xlfn.LET( _xlpm.camp,$B$3, _xlpm.prod,$D$3, _xlpm.moeda,$F$3, _xlpm.filtro,(Tabela2[Campanha]=_xlpm.camp)* (Tabela2[Moeda]=_xlpm.moeda)* (Tabela2[Produto Agrícola]=IF(_xlpm.prod="","",_xlpm.prod))* (Tabela2[Produto Financeiro]="Syngenta"), IFERROR(INDEX(_xlfn._xlws.FILTER(Tabela2[Taxa (a.m.)],_xlpm.filtro,""),1),0) )} -> 0.0185
A19: VALOR (-) DESCONTO + JUROS | B19: {=_xlfn.LET( _xlpm.pv,N($B$16), _xlpm.desc,N($B$17), _xlpm.taxa,N($B$18), _xlpm.tipo,$B$21, _xlpm.periodo,$B$22, _xlpm.n,IF(UPPER(_xlpm.periodo)="UTEIS",N($B$26),N($B$24)), _xlpm.vf,_xlpm.pv*(1-_xlpm.desc), _xlpm.vf + IF(UPPER(_xlpm.tipo)="SIMPLES",_xlpm.vf*_xlpm.taxa*_xlpm.n,_xlpm.vf*((1+_xlpm.taxa)^_xlpm.n-1)) )} -> 104.77727 | D19: =_xlfn.LET( _xlpm.pv,N($D$16), _xlpm.desc,N($D$17), _xlpm.taxa,N($D$18), _xlpm.tipo,D$21, _xlpm.periodo,$D$22, _xlpm.n,IF(UPPER(_xlpm.periodo)="UTEIS",N($D$26),N($D$24)), _xlpm.vf,_xlpm.pv*(1-_xlpm.desc), _xlpm.vf + IF(UPPER(_xlpm.tipo)="SIMPLES",_xlpm.vf*_xlpm.taxa*_xlpm.n,_xlpm.vf*((1+_xlpm.taxa)^_xlpm.n-1)) ) -> 109.55833 | F19: {=_xlfn.LET( _xlpm.pv,N($F$16), _xlpm.desc,N($F$17), _xlpm.taxa,N($F$18), _xlpm.tipo,F$21, _xlpm.periodo,$F$22, _xlpm.n,IF(UPPER(_xlpm.periodo)="UTEIS",N($F$26),N($F$24)), _xlpm.vf,_xlpm.pv*(1-_xlpm.desc), _xlpm.vf + IF(UPPER(_xlpm.tipo)="SIMPLES",_xlpm.vf*_xlpm.taxa*_xlpm.n,_xlpm.vf*((1+_xlpm.taxa)^_xlpm.n-1)) )} -> 109.55833
A20: Incentivo | B20: {=_xlfn.LET( _xlpm.camp,$B$3, _xlpm.prod,$D$3, _xlpm.moeda,$F$3, _xlpm.filtro,(Tabela2[Campanha]=_xlpm.camp)* (Tabela2[Moeda]=_xlpm.moeda)* (Tabela2[Produto Agrícola]=IF(_xlpm.prod="","",_xlpm.prod))* (Tabela2[Produto Financeiro]="Syde"), IFERROR(INDEX(_xlfn._xlws.FILTER(Tabela2[Incentivo],_xlpm.filtro,""),1),0) )} -> 0 | D20: {=_xlfn.LET( _xlpm.camp,$B$3, _xlpm.prod,$D$3, _xlpm.moeda,$F$3, _xlpm.filtro,(Tabela2[Campanha]=_xlpm.camp)* (Tabela2[Moeda]=_xlpm.moeda)* (Tabela2[Produto Agrícola]=IF(_xlpm.prod="","",_xlpm.prod))* (Tabela2[Produto Financeiro]="Fiso"), IFERROR(INDEX(_xlfn._xlws.FILTER(Tabela2[Incentivo],_xlpm.filtro,""),1),0) )} -> 0.03 | F20: {=_xlfn.LET( _xlpm.camp,$B$3, _xlpm.prod,$D$3, _xlpm.moeda,$F$3, _xlpm.filtro,(Tabela2[Campanha]=_xlpm.camp)* (Tabela2[Moeda]=_xlpm.moeda)* (Tabela2[Produto Agrícola]=IF(_xlpm.prod="","",_xlpm.prod))* (Tabela2[Produto Financeiro]="Syngenta"), IFERROR(INDEX(_xlfn._xlws.FILTER(Tabela2[Incentivo],_xlpm.filtro,""),1),0) )} -> 0
A21: Tipo de Juros | B21: {=_xlfn.LET( _xlpm.camp,$B$3, _xlpm.prod,$D$3, _xlpm.moeda,$F$3, _xlpm.filtro,(Tabela2[Campanha]=_xlpm.camp)* (Tabela2[Moeda]=_xlpm.moeda)* (Tabela2[Produto Agrícola]=IF(_xlpm.prod="","",_xlpm.prod))* (Tabela2[Produto Financeiro]="Syde"), IFERROR(INDEX(_xlfn._xlws.FILTER(Tabela2[Tipo Juros],_xlpm.filtro,""),1),"") )} -> Composto | D21: {=_xlfn.LET( _xlpm.camp,$B$3, _xlpm.prod,$D$3, _xlpm.moeda,$F$3, _xlpm.filtro,(Tabela2[Campanha]=_xlpm.camp)* (Tabela2[Moeda]=_xlpm.moeda)* (Tabela2[Produto Agrícola]=IF(_xlpm.prod="","",_xlpm.prod))* (Tabela2[Produto Financeiro]="Fiso"), IFERROR(INDEX(_xlfn._xlws.FILTER(Tabela2[Tipo Juros],_xlpm.filtro,""),1),"") )} -> Simples | F21: {=_xlfn.LET( _xlpm.camp,$B$3, _xlpm.prod,$D$3, _xlpm.moeda,$F$3, _xlpm.filtro,(Tabela2[Campanha]=_xlpm.camp)* (Tabela2[Moeda]=_xlpm.moeda)* (Tabela2[Produto Agrícola]=IF(_xlpm.prod="","",_xlpm.prod))* (Tabela2[Produto Financeiro]="Syngenta"), IFERROR(INDEX(_xlfn._xlws.FILTER(Tabela2[Tipo Juros],_xlpm.filtro,""),1),"") )} -> Simples
A22: Dias üteis ou Corridos? | B22: {=_xlfn.LET( _xlpm.camp,$B$3, _xlpm.prod,$D$3, _xlpm.moeda,$F$3, _xlpm.filtro,(Tabela2[Campanha]=_xlpm.camp)* (Tabela2[Moeda]=_xlpm.moeda)* (Tabela2[Produto Agrícola]=IF(_xlpm.prod="","",_xlpm.prod))* (Tabela2[Produto Financeiro]="Syde"), IFERROR(INDEX(_xlfn._xlws.FILTER(Tabela2[Cálculo Período],_xlpm.filtro,""),1),"") )} -> Uteis | D22: {=_xlfn.LET( _xlpm.camp,$B$3, _xlpm.prod,$D$3, _xlpm.moeda,$F$3, _xlpm.filtro,(Tabela2[Campanha]=_xlpm.camp)* (Tabela2[Moeda]=_xlpm.moeda)* (Tabela2[Produto Agrícola]=IF(_xlpm.prod="","",_xlpm.prod))* (Tabela2[Produto Financeiro]="Fiso"), IFERROR(INDEX(_xlfn._xlws.FILTER(Tabela2[Cálculo Período],_xlpm.filtro,""),1),"") )} -> Corridos | F22: {=_xlfn.LET( _xlpm.camp,$B$3, _xlpm.prod,$D$3, _xlpm.moeda,$F$3, _xlpm.filtro,(Tabela2[Campanha]=_xlpm.camp)* (Tabela2[Moeda]=_xlpm.moeda)* (Tabela2[Produto Agrícola]=IF(_xlpm.prod="","",_xlpm.prod))* (Tabela2[Produto Financeiro]="Syngenta"), IFERROR(INDEX(_xlfn._xlws.FILTER(Tabela2[Cálculo Período],_xlpm.filtro,""),1),"") )} -> Corridos
A23: Qtd Dias Corridos | B23: =IF(OR($B$8="",$D$8=""),"",$D$8-$B$8) -> 155 | D23: =IF(OR($B$8="",$D$8=""),"",$D$8-$B$8) -> 155 | F23: =IF(OR($B$8="",$D$8=""),"",$D$8-$B$8) -> 155
A24: Qtd Meses (P/ Dias Corridos) | B24: =IF(OR($B$8="",$D$8=""),"",($D$8-$B$8)/30) -> 5.1666667 | D24: =IF(OR($B$8="",$D$8=""),"",($D$8-$B$8)/30) -> 5.1666667 | F24: =IF(OR($B$8="",$D$8=""),"",($D$8-$B$8)/30) -> 5.1666667
A25: Qtd Dias Úteis | B25: =NETWORKDAYS($B$8,$D$8,Feriados!$A$2:$A$1000)-1 -> 105 | D25: =NETWORKDAYS($B$8,$D$8,Feriados!$A$2:$A$1000)-1 -> 105 | F25: =NETWORKDAYS($B$8,$D$8,Feriados!$A$2:$A$1000)-1 -> 105
A26: Qtd Meses (Por dias úteis) | B26: =IF($B$25="","",$B$25/22) -> 4.7727273 | D26: =IF($D$25="","",$D$25/22) -> 4.7727273 | F26: =IF($F$25="","",$F$25/22) -> 4.7727273
A27: Valor Final a Pagar | B27: =IFERROR(N($B$19)*(1-N($B$20)),"") -> 104.77727 | D27: =IFERROR(N($D$19)*(1-N($D$20)),"") -> 106.27158 | F27: =IFERROR(N($F$19)*(1-N($F$20)),"") -> 109.55833
A28: % Custo da Operação | B28: =IFERROR($B$27/N($B$16)-1,"") -> 0.047772689 | D28: =IFERROR($D$27/N($D$16)-1,"") -> 0.062715833 | F28: =IFERROR($F$27/N($F$16)-1,"") -> 0.095583333
A29: % a.m | B29: {=_xlfn.LET( _xlpm.n,N($B$24), _xlpm.fator,IFERROR(N($B$27)/N($B$16),""), _xlpm.tipo,$B$21, IFERROR((_xlpm.fator-1)/_xlpm.n,"") )} -> 0.0092463269 | D29: {=_xlfn.LET( _xlpm.n,N($D$24), _xlpm.fator,IFERROR(N($D$27)/N($D$16),""), _xlpm.tipo,$D$21, IFERROR((_xlpm.fator-1)/_xlpm.n,"") )} -> 0.012138548 | F29: {=_xlfn.LET( _xlpm.n,N($F$24), _xlpm.fator,IFERROR(N($F$27)/N($F$16),""), _xlpm.tipo,$F$21, IFERROR((_xlpm.fator-1)/_xlpm.n,"") )} -> 0.0185
A31: Racional de Cálculo
A32: Juros Simples | B32: Valor Final = (PV × (1 − DescontoComercial)) × (1 + taxa × n) × (1 - Incentivo)
A33: Juros Compostos | B33: Valor Final = (PV × (1 − DescontoComercial)) × (1 + taxa)^n × (1 - Incentivo)
A34: Qtd Dias Úteis | B34: Dias entre (Vencimento - Desembolso) - Finais de Semana - Feriados (Aba "Feriados") -1
A35: Qtd Meses por Dias Úteis | B35: Dias úteis / 22 dias (Equivalente a um mês)
A36: Qtd Meses por dias Corridos | B36: Dias Corridos (Vencimento - Desembolso) / 30dias (Equivalente a um mês)
A37: % a.m Juros Simples | B37: (VFP / PV − 1) / n
A38: % a.m Juros Composto | B38: VFP / PV)^(1/n) − 1
A39: PV = Valor Solicitado
A40: VF = Valor Financiado (após desconto)
A41: VFP = Valor Final a Pagar (já com juros e incentivo, se aplicável)
A42: n = Quantidade de meses

Sheet Feriados
A1: Data | B1: Descrição
A2: 45658 | B2: quarta-feira | C2: Confraternização Universal
A3: 45719 | B3: segunda-feira | C3: Carnaval
A4: 45720 | B4: terça-feira | C4: Carnaval
A5: 45765 | B5: sexta-feira | C5: Paixão de Cristo
A6: 45768 | B6: segunda-feira | C6: Tiradentes
A7: 45778 | B7: quinta-feira | C7: Dia do Trabalho
A8: 45827 | B8: quinta-feira | C8: Corpus Christi
A9: 45907 | B9: domingo | C9: Independência do Brasil
A10: 45942 | B10: domingo | C10: Nossa Sr.a Aparecida - Padroeira do Brasil
A11: 45963 | B11: domingo | C11: Finados
A12: 45976 | B12: sábado | C12: Proclamação da República
A13: 46016 | B13: quinta-feira | C13: Natal
... A648: 65334 | B648: terça-feira | C648: Proclamação da República
